Workbook

Sheet v1.1
A1: Sheet by Hematite based on 1.1 data provided by @Kaphotics!
A2: Pokémon | C2: Sticker | D2: Lv | E2: Ability | G2: Item | H2: Moves | I2: Nature | J2: EVs | P2: IVs
J3: HP | K3: Atk | L3: Def | M3: SpA | N3: SpD | O3: Spe
B4: Trainer ID 1 | D4: Youngster Tristan
A5: =IF(COUNTIF('Icon Lookup'!C:C,B5)>0,LOOKUP(B5,'Icon Lookup'!C:C,'Icon Lookup'!B:B),"") | B5: Starly | D5: 5 | E5: Keen Eye | H5: Tackle / Growl / Quick Attack | I5: Jolly | J5: 0 | K5: 0 | L5: 0 | M5: 0 | N5: 0 | O5: 0 | P5: 0 | Q5: 0 | R5: 0 | S5: 0 | T5: 0 | U5: 0
B6: Trainer ID 2 | D6: Youngster Logan
A7: =IF(COUNTIF('Icon Lookup'!C:C,B7)>0,LOOKUP(B7,'Icon Lookup'!C:C,'Icon Lookup'!B:B),"") | B7: Shinx | D7: 5 | E7: Intimidate | H7: Tackle / Leer / Thunder Shock | I7: Jolly | J7: 0 | K7: 0 | L7: 0 | M7: 0 | N7: 0 | O7: 0 | P7: 0 | Q7: 0 | R7: 0 | S7: 0 | T7: 0 | U7: 0
B8: Trainer ID 3 | D8: Lass Natalie
A9: =IF(COUNTIF('Icon Lookup'!C:C,B9)>0,LOOKUP(B9,'Icon Lookup'!C:C,'Icon Lookup'!B:B),"") | B9: Bidoof | D9: 3 | E9: Unaware | H9: Tackle / Growl | I9: Jolly | J9: 0 | K9: 0 | L9: 0 | M9: 0 | N9: 0 | O9: 0 | P9: 0 | Q9: 0 | R9: 0 | S9: 0 | T9: 0 | U9: 0
A10: =IF(COUNTIF('Icon Lookup'!C:C,B10)>0,LOOKUP(B10,'Icon Lookup'!C:C,'Icon Lookup'!B:B),"") | B10: Bidoof | D10: 3 | E10: Unaware | H10: Tackle / Growl | I10: Jolly | J10: 0 | K10: 0 | L10: 0 | M10: 0 | N10: 0 | O10: 0 | P10: 0 | Q10: 0 | R10: 0 | S10: 0 | T10: 0 | U10: 0
B11: Trainer ID 4 | D11: Youngster Michael
A12: =IF(COUNTIF('Icon Lookup'!C:C,B12)>0,LOOKUP(B12,'Icon Lookup'!C:C,'Icon Lookup'!B:B),"") | B12: Bidoof | D12: 5 | E12: Unaware | H12: Tackle / Growl / Defense Curl | I12: Docile | J12: 0 | K12: 0 | L12: 0 | M12: 0 | N12: 0 | O12: 0 | P12: 0 | Q12: 0 | R12: 0 | S12: 0 | T12: 0 | U12: 0
A13: =IF(COUNTIF('Icon Lookup'!C:C,B13)>0,LOOKUP(B13,'Icon Lookup'!C:C,'Icon Lookup'!B:B),"") | B13: Zubat | D13: 5 | E13: Inner Focus | H13: Absorb / Supersonic / Astonish | I13: Hasty | J13: 0 | K13: 0 | L13: 0 | M13: 0 | N13: 0 | O13: 0 | P13: 0 | Q13: 0 | R13: 0 | S13: 0 | T13: 0 | U13: 0
B14: Trainer ID 5 | D14: Youngster Tyler
A15: =IF(COUNTIF('Icon Lookup'!C:C,B15)>0,LOOKUP(B15,'Icon Lookup'!C:C,'Icon Lookup'!B:B),"") | B15: Magikarp | D15: 5 | E15: Swift Swim | H15: Splash | I15: Naive | J15: 0 | K15: 0 | L15: 0 | M15: 0 | N15: 0 | O15: 0 | P15: 0 | Q15: 0 | R15: 0 | S15: 0 | T15: 0 | U15: 0
A16: =IF(COUNTIF('Icon Lookup'!C:C,B16)>0,LOOKUP(B16,'Icon Lookup'!C:C,'Icon Lookup'!B:B),"") | B16: Starly | D16: 5 | E16: Keen Eye | H16: Tackle / Growl / Quick Attack | I16: Docile | J16: 0 | K16: 0 | L16: 0 | M16: 0 | N16: 0 | O16: 0 | P16: 0 | Q16: 0 | R16: 0 | S16: 0 | T16: 0 | U16: 0
B17: Trainer ID 6 | D17: Lass Samantha
A18: =IF(COUNTIF('Icon Lookup'!C:C,B18)>0,LOOKUP(B18,'Icon Lookup'!C:C,'Icon Lookup'!B:B),"") | B18: Budew | D18: 7 | E18: Poison Point | H18: Absorb / Growth / Stun Spore / Worry Seed | I18: Timid | J18: 0 | K18: 0 | L18: 0 | M18: 0 | N18: 0 | O18: 0 | P18: 0 | Q18: 0 | R18: 0 | S18: 0 | T18: 0 | U18: 0
B19: Trainer ID 7 | D19: Lass Sarah
A20: =IF(COUNTIF('Icon Lookup'!C:C,B20)>0,LOOKUP(B20,'Icon Lookup'!C:C,'Icon Lookup'!B:B),"") | B20: Bidoof | D20: 7 | E20: Unaware | H20: Tackle / Growl / Defense Curl | I20: Jolly | J20: 0 | K20: 0 | L20: 0 | M20: 0 | N20: 0 | O20: 0 | P20: 0 | Q20: 0 | R20: 0 | S20: 0 | T20: 0 | U20: 0
B21: Trainer ID 8 | D21: Bug Catcher Brandon
A22: =IF(COUNTIF('Icon Lookup'!C:C,B22)>0,LOOKUP(B22,'Icon Lookup'!C:C,'Icon Lookup'!B:B),"") | B22: Kricketot | D22: 7 | E22: Shed Skin | H22: Growl / Pound / Struggle Bug | I22: Timid | J22: 0 | K22: 0 | L22: 0 | M22: 0 | N22: 0 | O22: 0 | P22: 0 | Q22: 0 | R22: 0 | S22: 0 | T22: 0 | U22: 0
A23: =IF(COUNTIF('Icon Lookup'!C:C,B23)>0,LOOKUP(B23,'Icon Lookup'!C:C,'Icon Lookup'!B:B),"") | B23: Wurmple | D23: 7 | E23: Shield Dust | H23: Tackle / String Shot / Poison Sting | I23: Timid | J23: 0 | K23: 0 | L23: 0 | M23: 0 | N23: 0 | O23: 0 | P23: 0 | Q23: 0 | R23: 0 | S23: 0 | T23: 0 | U23: 0
B24: Trainer ID 9 | D24: Aroma Lady Teighler
A25: =IF(COUNTIF('Icon Lookup'!C:C,B25)>0,LOOKUP(B25,'Icon Lookup'!C:C,'Icon Lookup'!B:B),"") | B25: Budew | D25: 7 | E25: Poison Point | H25: Absorb / Growth / Stun Spore / Worry Seed | I25: Timid | J25: 0 | K25: 0 | L25: 0 | M25: 0 | N25: 0 | O25: 0 | P25: 0 | Q25: 0 | R25: 0 | S25: 0 | T25: 0 | U25: 0
A26: =IF(COUNTIF('Icon Lookup'!C:C,B26)>0,LOOKUP(B26,'Icon Lookup'!C:C,'Icon Lookup'!B:B),"") | B26: Cherubi | D26: 7 | E26: Chlorophyll | H26: Morning Sun / Tackle / Leafage | I26: Timid | J26: 0 | K26: 0 | L26: 0 | M26: 0 | N26: 0 | O26: 0 | P26: 0 | Q26: 0 | R26: 0 | S26: 0 | T26: 0 | U26: 0
B27: Trainer ID 10 | D27: Twins Liv
A28: =IF(COUNTIF('Icon Lookup'!C:C,B28)>0,LOOKUP(B28,'Icon Lookup'!C:C,'Icon Lookup'!B:B),"") | B28: Pachirisu | D28: 9 | E28: Pickup | H28: Growl / Baby-Doll Eyes / Quick Attack / Charm | I28: Quirky | J28: 0 | K28: 0 | L28: 0 | M28: 0 | N28: 0 | O28: 0 | P28: 0 | Q28: 0 | R28: 0 | S28: 0 | T28: 0 | U28: 0
B29: Trainer ID 11 | D29: Twins Liz
A30: =IF(COUNTIF('Icon Lookup'!C:C,B30)>0,LOOKUP(B30,'Icon Lookup'!C:C,'Icon Lookup'!B:B),"") | B30: Pachirisu | D30: 9 | E30: Pickup | H30: Growl / Baby-Doll Eyes / Quick Attack / Charm | I30: Quirky | J30: 0 | K30: 0 | L30: 0 | M30: 0 | N30: 0 | O30: 0 | P30: 0 | Q30: 0 | R30: 0 | S30: 0 | T30: 0 | U30: 0
B31: Trainer ID 12 | D31: Camper Jacob
A32: =IF(COUNTIF('Icon Lookup'!C:C,B32)>0,LOOKUP(B32,'Icon Lookup'!C:C,'Icon Lookup'!B:B),"") | B32: Ponyta | D32: 14 | E32: Flash Fire | H32: Tackle / Growl / Tail Whip / Ember | I32: Hasty | J32: 0 | K32: 0 | L32: 0 | M32: 0 | N32: 0 | O32: 0 | P32: 0 | Q32: 0 | R32: 0 | S32: 0 | T32: 0 | U32: 0
B33: Trainer ID 13 | D33: Picnicker Siena
A34: =IF(COUNTIF('Icon Lookup'!C:C,B34)>0,LOOKUP(B34,'Icon Lookup'!C:C,'Icon Lookup'!B:B),"") | B34: Shinx | D34: 12 | E34: Intimidate | H34: Tackle / Leer / Thunder Shock / Bite | I34: Jolly | J34: 0 | K34: 0 | L34: 0 | M34: 0 | N34: 0 | O34: 0 | P34: 0 | Q34: 0 | R34: 0 | S34: 0 | T34: 0 | U34: 0
A35: =IF(COUNTIF('Icon Lookup'!C:C,B35)>0,LOOKUP(B35,'Icon Lookup'!C:C,'Icon Lookup'!B:B),"") | B35: Pachirisu | D35: 12 | E35: Pickup | H35: Growl / Baby-Doll Eyes / Quick Attack / Charm | I35: Quirky | J35: 0 | K35: 0 | L35: 0 | M35: 0 | N35: 0 | O35: 0 | P35: 0 | Q35: 0 | R35: 0 | S35: 0 | T35: 0 | U35: 0
B36: Trainer ID 14 | D36: Hiker Daniel
A37: =IF(COUNTIF('Icon Lookup'!C:C,B37)>0,LOOKUP(B37,'Icon Lookup'!C:C,'Icon Lookup'!B:B),"") | B37: Geodude | D37: 11 | E37: Rock Head | H37: Tackle / Defense Curl / Rock Polish / Rollout | I37: Relaxed | J37: 0 | K37: 0 | L37: 0 | M37: 0 | N37: 0 | O37: 0 | P37: 0 | Q37: 0 | R37: 0 | S37: 0 | T37: 0 | U37: 0
A38: =IF(COUNTIF('Icon Lookup'!C:C,B38)>0,LOOKUP(B38,'Icon Lookup'!C:C,'Icon Lookup'!B:B),"") | B38: Machop | D38: 11 | E38: No Guard | H38: Low Kick / Leer / Focus Energy / Revenge | I38: Relaxed | J38: 0 | K38: 0 | L38: 0 | M38: 0 | N38: 0 | O38: 0 | P38: 0 | Q38: 0 | R38: 0 | S38: 0 | T38: 0 | U38: 0
A39: =IF(COUNTIF('Icon Lookup'!C:C,B39)>0,LOOKUP(B39,'Icon Lookup'!C:C,'Icon Lookup'!B:B),"") | B39: Geodude | D39: 11 | E39: Rock Head | H39: Tackle / Defense Curl / Rock Polish / Rollout | I39: Relaxed | J39: 0 | K39: 0 | L39: 0 | M39: 0 | N39: 0 | O39: 0 | P39: 0 | Q39: 0 | R39: 0 | S39: 0 | T39: 0 | U39: 0
A40: =IF(COUNTIF('Icon Lookup'!C:C,B40)>0,LOOKUP(B40,'Icon Lookup'!C:C,'Icon Lookup'!B:B),"") | B40: Bidoof | D40: 11 | E40: Unaware | H40: Tackle / Growl / Defense Curl / Rollout | I40: Hardy | J40: 0 | K40: 0 | L40: 0 | M40: 0 | N40: 0 | O40: 0 | P40: 0 | Q40: 0 | R40: 0 | S40: 0 | T40: 0 | U40: 0
...

Sheet v1.0
A1: Sheet by Hematite based on data provided by @GhostsSoup! (Trainer names and classes later added based on data provided by @Kaphotics!)
A2: Pokémon | C2: Sticker | D2: Lv | E2: Ability | G2: Item | H2: Moves | I2: Nature | J2: EVs | P2: IVs
J3: HP | K3: Atk | L3: Def | M3: SpA | N3: SpD | O3: Spe
A4: =IF(COUNTIF('Icon Lookup'!C:C,B4)>0,LOOKUP(B4,'Icon Lookup'!C:C,'Icon Lookup'!B:B),"") | B4: Trainer ID 1 | D4: Youngster Tristan
A5: =IF(COUNTIF('Icon Lookup'!C:C,B5)>0,LOOKUP(B5,'Icon Lookup'!C:C,'Icon Lookup'!B:B),"") | B5: Starly | D5: 5 | E5: Keen Eye | H5: Tackle / Growl / Quick Attack | I5: Jolly | J5: 0 | K5: 0 | L5: 0 | M5: 0 | N5: 0 | O5: 0 | P5: 0 | Q5: 0 | R5: 0 | S5: 0 | T5: 0 | U5: 0
A6: =IF(COUNTIF('Icon Lookup'!C:C,B6)>0,LOOKUP(B6,'Icon Lookup'!C:C,'Icon Lookup'!B:B),"") | B6: Trainer ID 2 | D6: Youngster Logan
A7: =IF(COUNTIF('Icon Lookup'!C:C,B7)>0,LOOKUP(B7,'Icon Lookup'!C:C,'Icon Lookup'!B:B),"") | B7: Shinx | D7: 5 | E7: Intimidate | H7: Tackle / Leer / Thunder Shock | I7: Jolly | J7: 0 | K7: 0 | L7: 0 | M7: 0 | N7: 0 | O7: 0 | P7: 0 | Q7: 0 | R7: 0 | S7: 0 | T7: 0 | U7: 0
A8: =IF(COUNTIF('Icon Lookup'!C:C,B8)>0,LOOKUP(B8,'Icon Lookup'!C:C,'Icon Lookup'!B:B),"") | B8: Trainer ID 3 | D8: Lass Natalie
A9: =IF(COUNTIF('Icon Lookup'!C:C,B9)>0,LOOKUP(B9,'Icon Lookup'!C:C,'Icon Lookup'!B:B),"") | B9: Bidoof | D9: 3 | E9: Unaware | H9: Tackle / Growl | I9: Jolly | J9: 0 | K9: 0 | L9: 0 | M9: 0 | N9: 0 | O9: 0 | P9: 0 | Q9: 0 | R9: 0 | S9: 0 | T9: 0 | U9: 0
A10: =IF(COUNTIF('Icon Lookup'!C:C,B10)>0,LOOKUP(B10,'Icon Lookup'!C:C,'Icon Lookup'!B:B),"") | B10: Bidoof | D10: 3 | E10: Unaware | H10: Tackle / Growl | I10: Jolly | J10: 0 | K10: 0 | L10: 0 | M10: 0 | N10: 0 | O10: 0 | P10: 0 | Q10: 0 | R10: 0 | S10: 0 | T10: 0 | U10: 0
A11: =IF(COUNTIF('Icon Lookup'!C:C,B11)>0,LOOKUP(B11,'Icon Lookup'!C:C,'Icon Lookup'!B:B),"") | B11: Trainer ID 4 | D11: Youngster Michael
A12: =IF(COUNTIF('Icon Lookup'!C:C,B12)>0,LOOKUP(B12,'Icon Lookup'!C:C,'Icon Lookup'!B:B),"") | B12: Bidoof | D12: 5 | E12: Unaware | H12: Tackle / Growl / Defense Curl | I12: Docile | J12: 0 | K12: 0 | L12: 0 | M12: 0 | N12: 0 | O12: 0 | P12: 0 | Q12: 0 | R12: 0 | S12: 0 | T12: 0 | U12: 0
A13: =IF(COUNTIF('Icon Lookup'!C:C,B13)>0,LOOKUP(B13,'Icon Lookup'!C:C,'Icon Lookup'!B:B),"") | B13: Zubat | D13: 5 | E13: Inner Focus | H13: Absorb / Supersonic / Astonish | I13: Hasty | J13: 0 | K13: 0 | L13: 0 | M13: 0 | N13: 0 | O13: 0 | P13: 0 | Q13: 0 | R13: 0 | S13: 0 | T13: 0 | U13: 0
A14: =IF(COUNTIF('Icon Lookup'!C:C,B14)>0,LOOKUP(B14,'Icon Lookup'!C:C,'Icon Lookup'!B:B),"") | B14: Trainer ID 5 | D14: Youngster Tyler
A15: =IF(COUNTIF('Icon Lookup'!C:C,B15)>0,LOOKUP(B15,'Icon Lookup'!C:C,'Icon Lookup'!B:B),"") | B15: Magikarp | D15: 5 | E15: Swift Swim | H15: Splash | I15: Naive | J15: 0 | K15: 0 | L15: 0 | M15: 0 | N15: 0 | O15: 0 | P15: 0 | Q15: 0 | R15: 0 | S15: 0 | T15: 0 | U15: 0
A16: =IF(COUNTIF('Icon Lookup'!C:C,B16)>0,LOOKUP(B16,'Icon Lookup'!C:C,'Icon Lookup'!B:B),"") | B16: Starly | D16: 5 | E16: Keen Eye | H16: Tackle / Growl / Quick Attack | I16: Docile | J16: 0 | K16: 0 | L16: 0 | M16: 0 | N16: 0 | O16: 0 | P16: 0 | Q16: 0 | R16: 0 | S16: 0 | T16: 0 | U16: 0
A17: =IF(COUNTIF('Icon Lookup'!C:C,B17)>0,LOOKUP(B17,'Icon Lookup'!C:C,'Icon Lookup'!B:B),"") | B17: Trainer ID 6 | D17: Lass Samantha
A18: =IF(COUNTIF('Icon Lookup'!C:C,B18)>0,LOOKUP(B18,'Icon Lookup'!C:C,'Icon Lookup'!B:B),"") | B18: Budew | D18: 7 | E18: Poison Point | H18: Absorb / Growth / Stun Spore / Worry Seed | I18: Timid | J18: 0 | K18: 0 | L18: 0 | M18: 0 | N18: 0 | O18: 0 | P18: 0 | Q18: 0 | R18: 0 | S18: 0 | T18: 0 | U18: 0
A19: =IF(COUNTIF('Icon Lookup'!C:C,B19)>0,LOOKUP(B19,'Icon Lookup'!C:C,'Icon Lookup'!B:B),"") | B19: Trainer ID 7 | D19: Lass Sarah
A20: =IF(COUNTIF('Icon Lookup'!C:C,B20)>0,LOOKUP(B20,'Icon Lookup'!C:C,'Icon Lookup'!B:B),"") | B20: Bidoof | D20: 7 | E20: Unaware | H20: Tackle / Growl / Defense Curl | I20: Jolly | J20: 0 | K20: 0 | L20: 0 | M20: 0 | N20: 0 | O20: 0 | P20: 0 | Q20: 0 | R20: 0 | S20: 0 | T20: 0 | U20: 0
A21: =IF(COUNTIF('Icon Lookup'!C:C,B21)>0,LOOKUP(B21,'Icon Lookup'!C:C,'Icon Lookup'!B:B),"") | B21: Trainer ID 8 | D21: Bug Catcher Brandon
A22: =IF(COUNTIF('Icon Lookup'!C:C,B22)>0,LOOKUP(B22,'Icon Lookup'!C:C,'Icon Lookup'!B:B),"") | B22: Kricketot | D22: 7 | E22: Shed Skin | H22: Growl / Pound / Struggle Bug | I22: Timid | J22: 0 | K22: 0 | L22: 0 | M22: 0 | N22: 0 | O22: 0 | P22: 0 | Q22: 0 | R22: 0 | S22: 0 | T22: 0 | U22: 0
A23: =IF(COUNTIF('Icon Lookup'!C:C,B23)>0,LOOKUP(B23,'Icon Lookup'!C:C,'Icon Lookup'!B:B),"") | B23: Wurmple | D23: 7 | E23: Shield Dust | H23: Tackle / String Shot / Poison Sting | I23: Timid | J23: 0 | K23: 0 | L23: 0 | M23: 0 | N23: 0 | O23: 0 | P23: 0 | Q23: 0 | R23: 0 | S23: 0 | T23: 0 | U23: 0
A24: =IF(COUNTIF('Icon Lookup'!C:C,B24)>0,LOOKUP(B24,'Icon Lookup'!C:C,'Icon Lookup'!B:B),"") | B24: Trainer ID 9 | D24: Aroma Lady Teighler
A25: =IF(COUNTIF('Icon Lookup'!C:C,B25)>0,LOOKUP(B25,'Icon Lookup'!C:C,'Icon Lookup'!B:B),"") | B25: Budew | D25: 7 | E25: Poison Point | H25: Absorb / Growth / Stun Spore / Worry Seed | I25: Timid | J25: 0 | K25: 0 | L25: 0 | M25: 0 | N25: 0 | O25: 0 | P25: 0 | Q25: 0 | R25: 0 | S25: 0 | T25: 0 | U25: 0
A26: =IF(COUNTIF('Icon Lookup'!C:C,B26)>0,LOOKUP(B26,'Icon Lookup'!C:C,'Icon Lookup'!B:B),"") | B26: Cherubi | D26: 7 | E26: Chlorophyll | H26: Morning Sun / Tackle / Leafage | I26: Timid | J26: 0 | K26: 0 | L26: 0 | M26: 0 | N26: 0 | O26: 0 | P26: 0 | Q26: 0 | R26: 0 | S26: 0 | T26: 0 | U26: 0
A27: =IF(COUNTIF('Icon Lookup'!C:C,B27)>0,LOOKUP(B27,'Icon Lookup'!C:C,'Icon Lookup'!B:B),"") | B27: Trainer ID 10 | D27: Twins Liv
A28: =IF(COUNTIF('Icon Lookup'!C:C,B28)>0,LOOKUP(B28,'Icon Lookup'!C:C,'Icon Lookup'!B:B),"") | B28: Pachirisu | D28: 9 | E28: Pickup | H28: Growl / Baby-Doll Eyes / Quick Attack / Charm | I28: Quirky | J28: 0 | K28: 0 | L28: 0 | M28: 0 | N28: 0 | O28: 0 | P28: 0 | Q28: 0 | R28: 0 | S28: 0 | T28: 0 | U28: 0
A29: =IF(COUNTIF('Icon Lookup'!C:C,B29)>0,LOOKUP(B29,'Icon Lookup'!C:C,'Icon Lookup'!B:B),"") | B29: Trainer ID 11 | D29: Twins Liz
A30: =IF(COUNTIF('Icon Lookup'!C:C,B30)>0,LOOKUP(B30,'Icon Lookup'!C:C,'Icon Lookup'!B:B),"") | B30: Pachirisu | D30: 9 | E30: Pickup | H30: Growl / Baby-Doll Eyes / Quick Attack / Charm | I30: Quirky | J30: 0 | K30: 0 | L30: 0 | M30: 0 | N30: 0 | O30: 0 | P30: 0 | Q30: 0 | R30: 0 | S30: 0 | T30: 0 | U30: 0
A31: =IF(COUNTIF('Icon Lookup'!C:C,B31)>0,LOOKUP(B31,'Icon Lookup'!C:C,'Icon Lookup'!B:B),"") | B31: Trainer ID 12 | D31: Camper Jacob
A32: =IF(COUNTIF('Icon Lookup'!C:C,B32)>0,LOOKUP(B32,'Icon Lookup'!C:C,'Icon Lookup'!B:B),"") | B32: Ponyta | D32: 14 | E32: Flash Fire | H32: Tackle / Growl / Tail Whip / Ember | I32: Hasty | J32: 0 | K32: 0 | L32: 0 | M32: 0 | N32: 0 | O32: 0 | P32: 0 | Q32: 0 | R32: 0 | S32: 0 | T32: 0 | U32: 0
A33: =IF(COUNTIF('Icon Lookup'!C:C,B33)>0,LOOKUP(B33,'Icon Lookup'!C:C,'Icon Lookup'!B:B),"") | B33: Trainer ID 13 | D33: Picnicker Siena
A34: =IF(COUNTIF('Icon Lookup'!C:C,B34)>0,LOOKUP(B34,'Icon Lookup'!C:C,'Icon Lookup'!B:B),"") | B34: Shinx | D34: 12 | E34: Intimidate | H34: Tackle / Leer / Thunder Shock / Bite | I34: Jolly | J34: 0 | K34: 0 | L34: 0 | M34: 0 | N34: 0 | O34: 0 | P34: 0 | Q34: 0 | R34: 0 | S34: 0 | T34: 0 | U34: 0
A35: =IF(COUNTIF('Icon Lookup'!C:C,B35)>0,LOOKUP(B35,'Icon Lookup'!C:C,'Icon Lookup'!B:B),"") | B35: Pachirisu | D35: 12 | E35: Pickup | H35: Growl / Baby-Doll Eyes / Quick Attack / Charm | I35: Quirky | J35: 0 | K35: 0 | L35: 0 | M35: 0 | N35: 0 | O35: 0 | P35: 0 | Q35: 0 | R35: 0 | S35: 0 | T35: 0 | U35: 0
A36: =IF(COUNTIF('Icon Lookup'!C:C,B36)>0,LOOKUP(B36,'Icon Lookup'!C:C,'Icon Lookup'!B:B),"") | B36: Trainer ID 14 | D36: Hiker Daniel
A37: =IF(COUNTIF('Icon Lookup'!C:C,B37)>0,LOOKUP(B37,'Icon Lookup'!C:C,'Icon Lookup'!B:B),"") | B37: Geodude | D37: 11 | E37: Rock Head | H37: Tackle / Defense Curl / Rock Polish / Rollout | I37: Relaxed | J37: 0 | K37: 0 | L37: 0 | M37: 0 | N37: 0 | O37: 0 | P37: 0 | Q37: 0 | R37: 0 | S37: 0 | T37: 0 | U37: 0
A38: =IF(COUNTIF('Icon Lookup'!C:C,B38)>0,LOOKUP(B38,'Icon Lookup'!C:C,'Icon Lookup'!B:B),"") | B38: Machop | D38: 11 | E38: No Guard | H38: Low Kick / Leer / Focus Energy / Revenge | I38: Relaxed | J38: 0 | K38: 0 | L38: 0 | M38: 0 | N38: 0 | O38: 0 | P38: 0 | Q38: 0 | R38: 0 | S38: 0 | T38: 0 | U38: 0
A39: =IF(COUNTIF('Icon Lookup'!C:C,B39)>0,LOOKUP(B39,'Icon Lookup'!C:C,'Icon Lookup'!B:B),"") | B39: Geodude | D39: 11 | E39: Rock Head | H39: Tackle / Defense Curl / Rock Polish / Rollout | I39: Relaxed | J39: 0 | K39: 0 | L39: 0 | M39: 0 | N39: 0 | O39: 0 | P39: 0 | Q39: 0 | R39: 0 | S39: 0 | T39: 0 | U39: 0
A40: =IF(COUNTIF('Icon Lookup'!C:C,B40)>0,LOOKUP(B40,'Icon Lookup'!C:C,'Icon Lookup'!B:B),"") | B40: Bidoof | D40: 11 | E40: Unaware | H40: Tackle / Growl / Defense Curl / Rollout | I40: Hardy | J40: 0 | K40: 0 | L40: 0 | M40: 0 | N40: 0 | O40: 0 | P40: 0 | Q40: 0 | R40: 0 | S40: 0 | T40: 0 | U40: 0
...

Sheet Item Lookup
A1: friendball.png
B543: =IMAGE("https://www.serebii.net/itemdex/sprites/softsand.png")
B544: =IMAGE("https://www.serebii.net/itemdex/sprites/sitrusberry.png")
B560: =IMAGE("https://www.serebii.net/itemdex/sprites/blacksludge.png")
B561: =IMAGE("https://www.serebii.net/itemdex/sprites/wiseglasses.png")
B562: =IMAGE("https://www.serebii.net/itemdex/sprites/sitrusberry.png")
B563: =IMAGE("https://www.serebii.net/itemdex/sprites/flameorb.png")
B564: =IMAGE("https://www.serebii.net/itemdex/sprites/scopelens.png")
B566: =IMAGE("https://www.serebii.net/itemdex/sprites/leftovers.png")
B567: =IMAGE("https://www.serebii.net/itemdex/sprites/sitrusberry.png")
B568: =IMAGE("https://www.serebii.net/itemdex/sprites/softsand.png")
B569: =IMAGE("https://www.serebii.net/itemdex/sprites/rindoberry.png")
B570: =IMAGE("https://www.serebii.net/itemdex/sprites/chestoberry.png")
B572: =IMAGE("https://www.serebii.net/itemdex/sprites/widelens.png")
B573: =IMAGE("https://www.serebii.net/itemdex/sprites/lifeorb.png")
B574: =IMAGE("https://www.serebii.net/itemdex/sprites/sitrusberry.png")
B575: =IMAGE("https://www.serebii.net/itemdex/sprites/leftovers.png")
B576: =IMAGE("https://www.serebii.net/itemdex/sprites/focussash.png")
B578: =IMAGE("https://www.serebii.net/itemdex/sprites/lightclay.png")
B579: =IMAGE("https://www.serebii.net/itemdex/sprites/mentalherb.png")
B580: =IMAGE("https://www.serebii.net/itemdex/sprites/muscleband.png")
B581: =IMAGE("https://www.serebii.net/itemdex/sprites/lifeorb.png")
B582: =IMAGE("https://www.serebii.net/itemdex/sprites/sitrusberry.png")
B590: =IMAGE("https://www.serebii.net/itemdex/sprites/sitrusberry.png")
B591: =IMAGE("https://www.serebii.net/itemdex/sprites/expertbelt.png")
B592: =IMAGE("https://www.serebii.net/itemdex/sprites/leftovers.png")
B593: =IMAGE("https://www.serebii.net/itemdex/sprites/wiseglasses.png")
B594: =IMAGE("https://www.serebii.net/itemdex/sprites/flameorb.png")
B595: =IMAGE("https://www.serebii.net/itemdex/sprites/yacheberry.png")
B684: =IMAGE("https://www.serebii.net/itemdex/sprites/oranberry.png")
B737: =IMAGE("https://www.serebii.net/itemdex/sprites/miracleseed.png")
B738: =IMAGE("https://www.serebii.net/itemdex/sprites/sitrusberry.png")
B740: =IMAGE("https://www.serebii.net/itemdex/sprites/widelens.png")
B741: =IMAGE("https://www.serebii.net/itemdex/sprites/damprock.png")
B742: =IMAGE("https://www.serebii.net/itemdex/sprites/sitrusberry.png")
B744: =IMAGE("https://www.serebii.net/itemdex/sprites/lightclay.png")
B745: =IMAGE("https://www.serebii.net/itemdex/sprites/expertbelt.png")
B746: =IMAGE("https://www.serebii.net/itemdex/sprites/bigroot.png")
B748: =IMAGE("https://www.serebii.net/itemdex/sprites/zoomlens.png")
B749: =IMAGE("https://www.serebii.net/itemdex/sprites/colburberry.png")
...

Sheet Icon Lookup
A1: abomasnow | B1: =IMAGE("https://www.smogon.com/forums//media/minisprites/"&A1&".png",3) | C1: Abomasnow | D1: Grass | E1: Ice | F1: 90 | G1: 92 | H1: 75 | I1: 92 | J1: 85 | K1: 60 | L1: =SUM(F1:K1) -> 494
A2: abra | B2: =IMAGE("https://www.smogon.com/forums//media/minisprites/"&A2&".png",3) | C2: Abra | D2: Psychic | F2: 25 | G2: 20 | H2: 15 | I2: 105 | J2: 55 | K2: 90 | L2: =SUM(F2:K2) -> 310
A3: absol | B3: =IMAGE("https://www.smogon.com/forums//media/minisprites/"&A3&".png",3) | C3: Absol | D3: Dark | F3: 65 | G3: 130 | H3: 60 | I3: 75 | J3: 60 | K3: 75 | L3: =SUM(F3:K3) -> 465
A4: accelgor | B4: =IMAGE("https://www.smogon.com/forums//media/minisprites/"&A4&".png",3) | C4: Accelgor | D4: Bug | F4: 80 | G4: 70 | H4: 40 | I4: 100 | J4: 60 | K4: 145 | L4: =SUM(F4:K4) -> 495
A5: aegislash | B5: =IMAGE("https://www.smogon.com/forums//media/minisprites/"&A5&".png",3) | C5: Aegislash | D5: Steel | E5: Ghost | F5: 60 | G5: 50 | H5: 140 | I5: 50 | J5: 140 | K5: 60 | L5: =SUM(F5:K5) -> 500
A6: aerodactyl | B6: =IMAGE("https://www.smogon.com/forums//media/minisprites/"&A6&".png",3) | C6: Aerodactyl | D6: Rock | E6: Flying | F6: 80 | G6: 105 | H6: 65 | I6: 60 | J6: 75 | K6: 130 | L6: =SUM(F6:K6) -> 515
A7: aggron | B7: =IMAGE("https://www.smogon.com/forums//media/minisprites/"&A7&".png",3) | C7: Aggron | D7: Steel | E7: Rock | F7: 70 | G7: 110 | H7: 180 | I7: 60 | J7: 60 | K7: 50 | L7: =SUM(F7:K7) -> 530
A8: aipom | B8: =IMAGE("https://www.smogon.com/forums//media/minisprites/"&A8&".png",3) | C8: Aipom | D8: Normal | F8: 55 | G8: 70 | H8: 55 | I8: 40 | J8: 55 | K8: 85 | L8: =SUM(F8:K8) -> 360
A9: alakazam | B9: =IMAGE("https://www.smogon.com/forums//media/minisprites/"&A9&".png",3) | C9: Alakazam | D9: Psychic | F9: 55 | G9: 50 | H9: 45 | I9: 135 | J9: 95 | K9: 120 | L9: =SUM(F9:K9) -> 500
A10: alcremie | B10: =IMAGE("https://www.smogon.com/forums//media/minisprites/"&A10&".png",3) | C10: Alcremie | D10: Fairy | F10: 65 | G10: 60 | H10: 75 | I10: 110 | J10: 121 | K10: 64 | L10: =SUM(F10:K10) -> 495
A11: alomomola | B11: =IMAGE("https://www.smogon.com/forums//media/minisprites/"&A11&".png",3) | C11: Alomomola | D11: Water | F11: 165 | G11: 75 | H11: 80 | I11: 40 | J11: 45 | K11: 65 | L11: =SUM(F11:K11) -> 470
A12: altaria | B12: =IMAGE("https://www.smogon.com/forums//media/minisprites/"&A12&".png",3) | C12: Altaria | D12: Dragon | E12: Flying | F12: 75 | G12: 70 | H12: 90 | I12: 70 | J12: 105 | K12: 80 | L12: =SUM(F12:K12) -> 490
A13: amaura | B13: =IMAGE("https://www.smogon.com/forums//media/minisprites/"&A13&".png",3) | C13: Amaura | D13: Rock | E13: Ice | F13: 77 | G13: 59 | H13: 50 | I13: 67 | J13: 63 | K13: 46 | L13: =SUM(F13:K13) -> 362
A14: ambipom | B14: =IMAGE("https://www.smogon.com/forums//media/minisprites/"&A14&".png",3) | C14: Ambipom | D14: Normal | F14: 75 | G14: 100 | H14: 66 | I14: 60 | J14: 66 | K14: 115 | L14: =SUM(F14:K14) -> 482
A15: amoonguss | B15: =IMAGE("https://www.smogon.com/forums//media/minisprites/"&A15&".png",3) | C15: Amoonguss | D15: Grass | E15: Poison | F15: 114 | G15: 85 | H15: 70 | I15: 85 | J15: 80 | K15: 30 | L15: =SUM(F15:K15) -> 464
A16: ampharos | B16: =IMAGE("https://www.smogon.com/forums//media/minisprites/"&A16&".png",3) | C16: Ampharos | D16: Electric | F16: 90 | G16: 75 | H16: 85 | I16: 115 | J16: 90 | K16: 55 | L16: =SUM(F16:K16) -> 510
A17: anorith | B17: =IMAGE("https://www.smogon.com/forums//media/minisprites/"&A17&".png",3) | C17: Anorith | D17: Rock | E17: Bug | F17: 45 | G17: 95 | H17: 50 | I17: 40 | J17: 50 | K17: 75 | L17: =SUM(F17:K17) -> 355
A18: appletun | B18: =IMAGE("https://www.smogon.com/forums//media/minisprites/"&A18&".png",3) | C18: Appletun | D18: Grass | E18: Dragon | F18: 110 | G18: 85 | H18: 80 | I18: 100 | J18: 80 | K18: 30 | L18: =SUM(F18:K18) -> 485
A19: applin | B19: =IMAGE("https://www.smogon.com/forums//media/minisprites/"&A19&".png",3) | C19: Applin | D19: Grass | E19: Dragon | F19: 40 | G19: 40 | H19: 80 | I19: 40 | J19: 40 | K19: 20 | L19: =SUM(F19:K19) -> 260
A20: araquanid | B20: =IMAGE("https://www.smogon.com/forums//media/minisprites/"&A20&".png",3) | C20: Araquanid | D20: Water | E20: Bug | F20: 68 | G20: 70 | H20: 92 | I20: 50 | J20: 132 | K20: 42 | L20: =SUM(F20:K20) -> 454
A21: arbok | B21: =IMAGE("https://www.smogon.com/forums//media/minisprites/"&A21&".png",3) | C21: Arbok | D21: Poison | F21: 60 | G21: 95 | H21: 69 | I21: 65 | J21: 79 | K21: 80 | L21: =SUM(F21:K21) -> 448
A22: arcanine | B22: =IMAGE("https://www.smogon.com/forums//media/minisprites/"&A22&".png",3) | C22: Arcanine | D22: Fire | F22: 90 | G22: 110 | H22: 80 | I22: 100 | J22: 80 | K22: 95 | L22: =SUM(F22:K22) -> 555
A23: arceus | B23: =IMAGE("https://www.smogon.com/forums//media/minisprites/"&A23&".png",3) | C23: Arceus | D23: Normal | F23: 120 | G23: 120 | H23: 120 | I23: 120 | J23: 120 | K23: 120 | L23: =SUM(F23:K23) -> 720
A24: archen | B24: =IMAGE("https://www.smogon.com/forums//media/minisprites/"&A24&".png",3) | C24: Archen | D24: Rock | E24: Flying | F24: 55 | G24: 112 | H24: 45 | I24: 74 | J24: 45 | K24: 70 | L24: =SUM(F24:K24) -> 401
A25: archeops | B25: =IMAGE("https://www.smogon.com/forums//media/minisprites/"&A25&".png",3) | C25: Archeops | D25: Rock | E25: Flying | F25: 75 | G25: 140 | H25: 65 | I25: 112 | J25: 65 | K25: 110 | L25: =SUM(F25:K25) -> 567
A26: arctovish | B26: =IMAGE("https://www.smogon.com/forums//media/minisprites/"&A26&".png",3) | C26: Arctovish | D26: Water | E26: Ice | F26: 90 | G26: 90 | H26: 100 | I26: 80 | J26: 90 | K26: 55 | L26: =SUM(F26:K26) -> 505
A27: arctozolt | B27: =IMAGE("https://www.smogon.com/forums//media/minisprites/"&A27&".png",3) | C27: Arctozolt | D27: Electric | E27: Ice | F27: 90 | G27: 100 | H27: 90 | I27: 90 | J27: 80 | K27: 55 | L27: =SUM(F27:K27) -> 505
A28: argalis | B28: =IMAGE("https://www.smogon.com/forums//media/minisprites/"&A28&".png",3) | C28: Argalis | D28: Bug | E28: Psychic | F28: 60 | G28: 90 | H28: 89 | I28: 87 | J28: 40 | K28: 54 | L28: =SUM(F28:K28) -> 420
A29: arghonaut | B29: =IMAGE("https://www.smogon.com/forums//media/minisprites/"&A29&".png",3) | C29: Arghonaut | D29: Water | E29: Fighting | F29: 105 | G29: 110 | H29: 95 | I29: 70 | J29: 100 | K29: 75 | L29: =SUM(F29:K29) -> 555
A30: ariados | B30: =IMAGE("https://www.smogon.com/forums//media/minisprites/"&A30&".png",3) | C30: Ariados | D30: Bug | E30: Poison | F30: 70 | G30: 90 | H30: 70 | I30: 60 | J30: 70 | K30: 40 | L30: =SUM(F30:K30) -> 400
A31: armaldo | B31: =IMAGE("https://www.smogon.com/forums//media/minisprites/"&A31&".png",3) | C31: Armaldo | D31: Rock | E31: Bug | F31: 75 | G31: 125 | H31: 100 | I31: 70 | J31: 80 | K31: 45 | L31: =SUM(F31:K31) -> 495
A32: aromatisse | B32: =IMAGE("https://www.smogon.com/forums//media/minisprites/"&A32&".png",3) | C32: Aromatisse | D32: Fairy | F32: 101 | G32: 72 | H32: 72 | I32: 99 | J32: 89 | K32: 29 | L32: =SUM(F32:K32) -> 462
A33: aron | B33: =IMAGE("https://www.smogon.com/forums//media/minisprites/"&A33&".png",3) | C33: Aron | D33: Steel | E33: Rock | F33: 50 | G33: 70 | H33: 100 | I33: 40 | J33: 40 | K33: 30 | L33: =SUM(F33:K33) -> 330
A34: arrokuda | B34: =IMAGE("https://www.smogon.com/forums//media/minisprites/"&A34&".png",3) | C34: Arrokuda | D34: Water | F34: 41 | G34: 63 | H34: 40 | I34: 40 | J34: 30 | K34: 66 | L34: =SUM(F34:K34) -> 280
A35: articuno | B35: =IMAGE("https://www.smogon.com/forums//media/minisprites/"&A35&".png",3) | C35: Articuno | D35: Ice | E35: Flying | F35: 90 | G35: 85 | H35: 100 | I35: 95 | J35: 125 | K35: 85 | L35: =SUM(F35:K35) -> 580
A36: astrolotl | B36: =IMAGE("https://www.smogon.com/forums//media/minisprites/"&A36&".png",3) | C36: Astrolotl | D36: Fire | E36: Dragon | F36: 108 | G36: 108 | H36: 74 | I36: 92 | J36: 64 | K36: 114 | L36: =SUM(F36:K36) -> 560
A37: audino | B37: =IMAGE("https://www.smogon.com/forums//media/minisprites/"&A37&".png",3) | C37: Audino | D37: Normal | F37: 103 | G37: 60 | H37: 86 | I37: 60 | J37: 86 | K37: 50 | L37: =SUM(F37:K37) -> 445
A38: aurorus | B38: =IMAGE("https://www.smogon.com/forums//media/minisprites/"&A38&".png",3) | C38: Aurorus | D38: Rock | E38: Ice | F38: 123 | G38: 77 | H38: 72 | I38: 99 | J38: 92 | K38: 58 | L38: =SUM(F38:K38) -> 521
A39: aurumoth | B39: =IMAGE("https://www.smogon.com/forums//media/minisprites/"&A39&".png",3) | C39: Aurumoth | D39: Bug | E39: Psychic | F39: 110 | G39: 120 | H39: 99 | I39: 117 | J39: 60 | K39: 94 | L39: =SUM(F39:K39) -> 600
A40: avalugg | B40: =IMAGE("https://www.smogon.com/forums//media/minisprites/"&A40&".png",3) | C40: Avalugg | D40: Ice | F40: 95 | G40: 117 | H40: 184 | I40: 44 | J40: 46 | K40: 28 | L40: =SUM(F40:K40) -> 514
...

Sheet Changelog
A1: All sets changed between 1.0 data (provided by @GhostsSoup) and 1.1 data (provided by @Kaphotics). 1.0 is listed first and 1.1 directly below it for convenience!
A2: Pokémon | C2: Sticker | D2: Lv | E2: Ability | G2: Item | H2: Moves | I2: Nature | J2: EVs | P2: IVs
J3: HP | K3: Atk | L3: Def | M3: SpA | N3: SpD | O3: Spe
B4: Trainer ID 352 | D4: Pokémon Trainer Cedric | H4: (note: Cedric is the name used for Barry internally)
A5: =IF(COUNTIF('Icon Lookup'!C:C,B5)>0,LOOKUP(B5,'Icon Lookup'!C:C,'Icon Lookup'!B:B),"") | B5: Monferno | C5: ! | D5: 21 | E5: Blaze | H5: Mach Punch / Leer / Flame Wheel / Stealth Rock | I5: Jolly | J5: 12 | K5: 0 | L5: 4 | M5: 36 | N5: 4 | O5: 36 | P5: 11 | Q5: 11 | R5: 11 | S5: 11 | T5: 11 | U5: 11
A6: =IF(COUNTIF('Icon Lookup'!C:C,B6)>0,LOOKUP(B6,'Icon Lookup'!C:C,'Icon Lookup'!B:B),"") | B6: Monferno | C6: ! | D6: 21 | E6: Blaze | H6: Mach Punch / Leer / Flame Wheel / Stealth Rock | I6: Jolly | J6: 12 | K6: 36 | L6: 4 | M6: 0 | N6: 4 | O6: 36 | P6: 11 | Q6: 11 | R6: 11 | S6: 11 | T6: 11 | U6: 11
B7: Trainer ID 353 | D7: Pokémon Trainer Cedric | H7: (note: Cedric is the name used for Barry internally)
A8: =IF(COUNTIF('Icon Lookup'!C:C,B8)>0,LOOKUP(B8,'Icon Lookup'!C:C,'Icon Lookup'!B:B),"") | B8: Prinplup | C8: ! | D8: 21 | E8: Torrent | H8: Metal Claw / Bubble Beam / Stealth Rock / Grass Knot | I8: Timid | J8: 12 | K8: 36 | L8: 4 | M8: 0 | N8: 4 | O8: 36 | P8: 11 | Q8: 11 | R8: 11 | S8: 11 | T8: 11 | U8: 11
A9: =IF(COUNTIF('Icon Lookup'!C:C,B9)>0,LOOKUP(B9,'Icon Lookup'!C:C,'Icon Lookup'!B:B),"") | B9: Prinplup | C9: ! | D9: 21 | E9: Torrent | H9: Metal Claw / Bubble Beam / Stealth Rock / Grass Knot | I9: Timid | J9: 12 | K9: 0 | L9: 4 | M9: 36 | N9: 4 | O9: 36 | P9: 11 | Q9: 11 | R9: 11 | S9: 11 | T9: 11 | U9: 11
B10: Trainer ID 355 | D10: Pokémon Trainer Cedric | H10: (note: Cedric is the name used for Barry internally)
A11: =IF(COUNTIF('Icon Lookup'!C:C,B11)>0,LOOKUP(B11,'Icon Lookup'!C:C,'Icon Lookup'!B:B),"") | B11: Monferno | C11: ! | D11: 31 | E11: =IMAGE("https://www.serebii.net/itemdex/sprites/shellbell.png") | F11: Blaze | G11: Shell Bell | H11: Mach Punch / Leer / Power-Up Punch / Flame Wheel | I11: Jolly | J11: 36 | K11: 0 | L11: 12 | M11: 52 | N11: 12 | O11: 52 | P11: 11 | Q11: 11 | R11: 11 | S11: 11 | T11: 11 | U11: 11
A12: =IF(COUNTIF('Icon Lookup'!C:C,B12)>0,LOOKUP(B12,'Icon Lookup'!C:C,'Icon Lookup'!B:B),"") | B12: Monferno | C12: ! | D12: 31 | E12: =IMAGE("https://www.serebii.net/itemdex/sprites/shellbell.png") | F12: Blaze | G12: Shell Bell | H12: Mach Punch / Leer / Power-Up Punch / Flame Wheel | I12: Jolly | J12: 36 | K12: 52 | L12: 12 | M12: 0 | N12: 12 | O12: 52 | P12: 11 | Q12: 11 | R12: 11 | S12: 11 | T12: 11 | U12: 11
B13: Trainer ID 356 | D13: Pokémon Trainer Cedric | H13: (note: Cedric is the name used for Barry internally)
A14: =IF(COUNTIF('Icon Lookup'!C:C,B14)>0,LOOKUP(B14,'Icon Lookup'!C:C,'Icon Lookup'!B:B),"") | B14: Prinplup | C14: ! | D14: 31 | E14: =IMAGE("https://www.serebii.net/itemdex/sprites/seaincense.png") | F14: Torrent | G14: Sea Incense | H14: Metal Claw / Charm / Bubble Beam / Grass Knot | I14: Timid | J14: 36 | K14: 52 | L14: 12 | M14: 0 | N14: 12 | O14: 52 | P14: 11 | Q14: 11 | R14: 11 | S14: 11 | T14: 11 | U14: 11
A15: =IF(COUNTIF('Icon Lookup'!C:C,B15)>0,LOOKUP(B15,'Icon Lookup'!C:C,'Icon Lookup'!B:B),"") | B15: Prinplup | C15: ! | D15: 31 | E15: =IMAGE("https://www.serebii.net/itemdex/sprites/seaincense.png") | F15: Torrent | G15: Sea Incense | H15: Metal Claw / Charm / Bubble Beam / Grass Knot | I15: Timid | J15: 36 | K15: 0 | L15: 12 | M15: 52 | N15: 12 | O15: 52 | P15: 11 | Q15: 11 | R15: 11 | S15: 11 | T15: 11 | U15: 11
B16: Trainer ID 358 | D16: Pokémon Trainer Cedric | H16: (note: Cedric is the name used for Barry internally)
A17: =IF(COUNTIF('Icon Lookup'!C:C,B17)>0,LOOKUP(B17,'Icon Lookup'!C:C,'Icon Lookup'!B:B),"") | B17: Monferno | C17: ! | D17: 37 | E17: =IMAGE("https://www.serebii.net/itemdex/sprites/shellbell.png") | F17: Blaze | G17: Shell Bell | H17: Mach Punch / Power-Up Punch / Flame Wheel / Shadow Claw | I17: Jolly | J17: 48 | K17: 0 | L17: 24 | M17: 80 | N17: 24 | O17: 80 | P17: 11 | Q17: 11 | R17: 11 | S17: 11 | T17: 11 | U17: 11
A18: =IF(COUNTIF('Icon Lookup'!C:C,B18)>0,LOOKUP(B18,'Icon Lookup'!C:C,'Icon Lookup'!B:B),"") | B18: Monferno | C18: ! | D18: 37 | E18: =IMAGE("https://www.serebii.net/itemdex/sprites/shellbell.png") | F18: Blaze | G18: Shell Bell | H18: Mach Punch / Power-Up Punch / Flame Wheel / Shadow Claw | I18: Jolly | J18: 48 | K18: 80 | L18: 24 | M18: 0 | N18: 24 | O18: 80 | P18: 11 | Q18: 11 | R18: 11 | S18: 11 | T18: 11 | U18: 11
B19: Trainer ID 359 | D19: Pokémon Trainer Cedric | H19: (note: Cedric is the name used for Barry internally)
A20: =IF(COUNTIF('Icon Lookup'!C:C,B20)>0,LOOKUP(B20,'Icon Lookup'!C:C,'Icon Lookup'!B:B),"") | B20: Prinplup | C20: ! | D20: 37 | E20: =IMAGE("https://www.serebii.net/itemdex/sprites/seaincense.png") | F20: Torrent | G20: Sea Incense | H20: Metal Claw / Charm / Grass Knot / Brine | I20: Timid | J20: 48 | K20: 80 | L20: 24 | M20: 0 | N20: 24 | O20: 80 | P20: 11 | Q20: 11 | R20: 11 | S20: 11 | T20: 11 | U20: 11
A21: =IF(COUNTIF('Icon Lookup'!C:C,B21)>0,LOOKUP(B21,'Icon Lookup'!C:C,'Icon Lookup'!B:B),"") | B21: Prinplup | C21: ! | D21: 37 | E21: =IMAGE("https://www.serebii.net/itemdex/sprites/seaincense.png") | F21: Torrent | G21: Sea Incense | H21: Metal Claw / Charm / Grass Knot / Brine | I21: Timid | J21: 48 | K21: 0 | L21: 24 | M21: 80 | N21: 24 | O21: 80 | P21: 11 | Q21: 11 | R21: 11 | S21: 11 | T21: 11 | U21: 11
B22: Trainer ID 361 | D22: Pokémon Trainer Cedric | H22: (note: Cedric is the name used for Barry internally)
A23: =IF(COUNTIF('Icon Lookup'!C:C,B23)>0,LOOKUP(B23,'Icon Lookup'!C:C,'Icon Lookup'!B:B),"") | B23: Infernape | C23: ! | D23: 55 | E23: =IMAGE("https://www.serebii.net/itemdex/sprites/expertbelt.png") | F23: Blaze | G23: Expert Belt | H23: Close Combat / Flame Wheel / U-turn / Shadow Claw | I23: Jolly | J23: 52 | K23: 0 | L23: 52 | M23: 156 | N23: 52 | O23: 164 | P23: 11 | Q23: 11 | R23: 11 | S23: 11 | T23: 11 | U23: 11
A24: =IF(COUNTIF('Icon Lookup'!C:C,B24)>0,LOOKUP(B24,'Icon Lookup'!C:C,'Icon Lookup'!B:B),"") | B24: Infernape | C24: ! | D24: 55 | E24: =IMAGE("https://www.serebii.net/itemdex/sprites/expertbelt.png") | F24: Blaze | G24: Expert Belt | H24: Close Combat / Flame Wheel / U-turn / Shadow Claw | I24: Jolly | J24: 52 | K24: 156 | L24: 52 | M24: 0 | N24: 52 | O24: 164 | P24: 11 | Q24: 11 | R24: 11 | S24: 11 | T24: 11 | U24: 11
B25: Trainer ID 362 | D25: Pokémon Trainer Cedric | H25: (note: Cedric is the name used for Barry internally)
A26: =IF(COUNTIF('Icon Lookup'!C:C,B26)>0,LOOKUP(B26,'Icon Lookup'!C:C,'Icon Lookup'!B:B),"") | B26: Empoleon | C26: ! | D26: 55 | E26: =IMAGE("https://www.serebii.net/itemdex/sprites/quickclaw.png") | F26: Torrent | G26: Quick Claw | H26: Charm / Grass Knot / Brine / Flash Cannon | I26: Timid | J26: 52 | K26: 156 | L26: 52 | M26: 0 | N26: 52 | O26: 164 | P26: 11 | Q26: 11 | R26: 11 | S26: 11 | T26: 11 | U26: 11
A27: =IF(COUNTIF('Icon Lookup'!C:C,B27)>0,LOOKUP(B27,'Icon Lookup'!C:C,'Icon Lookup'!B:B),"") | B27: Empoleon | C27: ! | D27: 55 | E27: =IMAGE("https://www.serebii.net/itemdex/sprites/quickclaw.png") | F27: Torrent | G27: Quick Claw | H27: Charm / Grass Knot / Brine / Flash Cannon | I27: Timid | J27: 52 | K27: 0 | L27: 52 | M27: 156 | N27: 52 | O27: 164 | P27: 11 | Q27: 11 | R27: 11 | S27: 11 | T27: 11 | U27: 11
B28: Trainer ID 493 | D28: Pokémon Trainer Cedric | H28: (note: Cedric is the name used for Barry internally)
A29: =IF(COUNTIF('Icon Lookup'!C:C,B29)>0,LOOKUP(B29,'Icon Lookup'!C:C,'Icon Lookup'!B:B),"") | B29: Infernape | C29: ! | D29: 45 | E29: =IMAGE("https://www.serebii.net/itemdex/sprites/shellbell.png") | F29: Blaze | G29: Shell Bell | H29: Close Combat / Flame Wheel / U-turn / Shadow Claw | I29: Jolly | J29: 52 | K29: 0 | L29: 52 | M29: 124 | N29: 52 | O29: 164 | P29: 11 | Q29: 11 | R29: 11 | S29: 11 | T29: 11 | U29: 11
A30: =IF(COUNTIF('Icon Lookup'!C:C,B30)>0,LOOKUP(B30,'Icon Lookup'!C:C,'Icon Lookup'!B:B),"") | B30: Infernape | C30: ! | D30: 45 | E30: =IMAGE("https://www.serebii.net/itemdex/sprites/shellbell.png") | F30: Blaze | G30: Shell Bell | H30: Close Combat / Flame Wheel / U-turn / Shadow Claw | I30: Jolly | J30: 52 | K30: 124 | L30: 52 | M30: 0 | N30: 52 | O30: 164 | P30: 11 | Q30: 11 | R30: 11 | S30: 11 | T30: 11 | U30: 11
B31: Trainer ID 494 | D31: Pokémon Trainer Cedric | H31: (note: Cedric is the name used for Barry internally)
A32: =IF(COUNTIF('Icon Lookup'!C:C,B32)>0,LOOKUP(B32,'Icon Lookup'!C:C,'Icon Lookup'!B:B),"") | B32: Empoleon | C32: ! | D32: 45 | E32: =IMAGE("https://www.serebii.net/itemdex/sprites/seaincense.png") | F32: Torrent | G32: Sea Incense | H32: Metal Claw / Charm / Grass Knot / Brine | I32: Timid | J32: 52 | K32: 124 | L32: 52 | M32: 0 | N32: 52 | O32: 164 | P32: 11 | Q32: 11 | R32: 11 | S32: 11 | T32: 11 | U32: 11
A33: =IF(COUNTIF('Icon Lookup'!C:C,B33)>0,LOOKUP(B33,'Icon Lookup'!C:C,'Icon Lookup'!B:B),"") | B33: Empoleon | C33: ! | D33: 45 | E33: =IMAGE("https://www.serebii.net/itemdex/sprites/seaincense.png") | F33: Torrent | G33: Sea Incense | H33: Metal Claw / Charm / Grass Knot / Brine | I33: Timid | J33: 52 | K33: 0 | L33: 52 | M33: 124 | N33: 52 | O33: 164 | P33: 11 | Q33: 11 | R33: 11 | S33: 11 | T33: 11 | U33: 11
B34: Trainer ID 664 | D34: Pokémon Trainer Cedric | H34: (note: Cedric is the name used for Barry internally)
A35: =IF(COUNTIF('Icon Lookup'!C:C,B35)>0,LOOKUP(B35,'Icon Lookup'!C:C,'Icon Lookup'!B:B),"") | B35: Infernape | C35: ! | D35: 64 | E35: =IMAGE("https://www.serebii.net/itemdex/sprites/expertbelt.png") | F35: Blaze | G35: Expert Belt | H35: Close Combat / Flare Blitz / U-turn / Shadow Claw | I35: Jolly | J35: 52 | K35: 0 | L35: 52 | M35: 188 | N35: 52 | O35: 164 | P35: 11 | Q35: 11 | R35: 11 | S35: 11 | T35: 11 | U35: 11
A36: =IF(COUNTIF('Icon Lookup'!C:C,B36)>0,LOOKUP(B36,'Icon Lookup'!C:C,'Icon Lookup'!B:B),"") | B36: Infernape | C36: ! | D36: 64 | E36: =IMAGE("https://www.serebii.net/itemdex/sprites/expertbelt.png") | F36: Blaze | G36: Expert Belt | H36: Close Combat / Flare Blitz / U-turn / Shadow Claw | I36: Jolly | J36: 52 | K36: 188 | L36: 52 | M36: 0 | N36: 52 | O36: 164 | P36: 11 | Q36: 11 | R36: 11 | S36: 11 | T36: 11 | U36: 11
B37: Trainer ID 665 | D37: Pokémon Trainer Cedric | H37: (note: Cedric is the name used for Barry internally)
A38: =IF(COUNTIF('Icon Lookup'!C:C,B38)>0,LOOKUP(B38,'Icon Lookup'!C:C,'Icon Lookup'!B:B),"") | B38: Empoleon | C38: ! | D38: 64 | E38: =IMAGE("https://www.serebii.net/itemdex/sprites/quickclaw.png") | F38: Torrent | G38: Quick Claw | H38: Charm / Grass Knot / Surf / Flash Cannon | I38: Timid | J38: 52 | K38: 188 | L38: 52 | M38: 0 | N38: 52 | O38: 164 | P38: 11 | Q38: 11 | R38: 11 | S38: 11 | T38: 11 | U38: 11
A39: =IF(COUNTIF('Icon Lookup'!C:C,B39)>0,LOOKUP(B39,'Icon Lookup'!C:C,'Icon Lookup'!B:B),"") | B39: Empoleon | C39: ! | D39: 64 | E39: =IMAGE("https://www.serebii.net/itemdex/sprites/quickclaw.png") | F39: Torrent | G39: Quick Claw | H39: Charm / Grass Knot / Surf / Flash Cannon | I39: Timid | J39: 52 | K39: 0 | L39: 52 | M39: 188 | N39: 52 | O39: 164 | P39: 11 | Q39: 11 | R39: 11 | S39: 11 | T39: 11 | U39: 11
B40: Trainer ID 666 | D40: Pokémon Trainer Cedric | H40: (note: Cedric is the name used for Barry internally)
...
